Workbook

Sheet Bench Forecast
A1: Center | B1: Wk 01 | C1: Wk 02 | D1: Wk 03 | E1: Wk 04 | F1: Wk 05 | G1: Wk 06 | H1: Wk 07 | I1: Wk 08 | J1: Wk 09 | K1: Wk 10 | L1: Wk 11 | M1: Wk 12 | N1: Wk 13
A2: Baton Rouge | B2: 51 | C2: 39 | D2: 43 | E2: 46 | F2: 37 | G2: 44 | H2: 43 | I2: 38 | J2: 36 | K2: 49 | L2: 49 | M2: 49 | N2: 49
A3: Buffalo | B3: 5 | C3: 7 | D3: 5 | E3: 5 | F3: 3 | G3: 2 | H3: 2 | I3: 3 | J3: 4 | K3: 5 | L3: 5 | M3: 5 | N3: 5
A4: Calgary | B4: 27 | C4: 23 | D4: 19 | E4: 18 | F4: 20 | G4: 26 | H4: 41 | I4: 28 | J4: 29 | K4: 33 | L4: 33 | M4: 33 | N4: 33
A5: Halifax | B5: 24 | C5: 15 | D5: 10 | E5: 20 | F5: 20 | G5: 20 | H5: 23 | I5: 30 | J5: 30 | K5: 40 | L5: 40 | M5: 40 | N5: 40
A6: Lansing | B6: 14 | C6: 11 | D6: 14 | E6: 11 | F6: 11 | G6: 16 | H6: 15 | I6: 10 | J6: 10 | K6: 13 | L6: 14 | M6: 15 | N6: 15
A7: Monroe | B7: 12 | C7: 9 | D7: 4 | E7: 10 | F7: 9 | G7: 11 | H7: 12 | I7: 13 | J7: 13 | K7: 14 | L7: 14 | M7: 14 | N7: 12
A8: Quebec | B8: 13 | C8: 11 | D8: 9 | E8: 14 | F8: 14 | G8: 15 | H8: 19 | I8: 19 | J8: 22 | K8: 31 | L8: 32 | M8: 32 | N8: 33
A9: Grand Total | B9: =SUM(B2:B8) -> 146 | C9: =SUM(C2:C8) -> 115 | D9: =SUM(D2:D8) -> 104 | E9: =SUM(E2:E8) -> 124 | F9: =SUM(F2:F8) -> 114 | G9: =SUM(G2:G8) -> 134 | H9: =SUM(H2:H8) -> 155 | I9: =SUM(I2:I8) -> 141 | ... N9: =SUM(N2:N8) -> 187
A10: Bench % | B10: =+B9/$B$11 -> 0.072528564 | C10: =+C9/$B$11 -> 0.057128664 | D10: =+D9/$B$11 -> 0.051664183 | E10: =+E9/$B$11 -> 0.061599603 | F10: =+F9/$B$11 -> 0.056631893 | G10: =+G9/$B$11 -> 0.066567312 | H10: =+H9/$B$11 -> 0.076999503 | I10: =+I9/$B$11 -> 0.070044709 | ... N10: =+N9/$B$11 -> 0.092896175
A11: HC | B11: 2013

Sheet Historic Bench Data
A1: Year | B1: Quarter | C1: Week | D1: Baton Rouge | E1: East Lansing | F1: Monroe | G1: Buffalo | H1: Halifax | I1: Quebec | J1: Calgary | K1: NA CIC | L1: Wk
A2: 2025 | B2: 1Q | C2: WK 01 | D2: 88 | E2: 19 | F2: 46 | G2: 7 | H2: 42 | I2: 49 | J2: 17 | K2: =SUM(D2:J2) -> 268 | L2: =+B2&" "&C2 -> 1Q WK 01 | N2: Wk | O2: NA CIC
A3: 2025 | B3: 1Q | C3: WK 02 | D3: 117 | E3: 15 | F3: 32 | G3: 5 | H3: 50 | I3: 57 | J3: 14 | K3: =SUM(D3:J3) -> 290 | L3: =+B3&" "&C3 -> 1Q WK 02 | N3: 1Q WK 01 | O3: 268
A4: 2025 | B4: 1Q | C4: WK 03 | D4: 84 | E4: 13 | F4: 29 | G4: 5 | H4: 42 | I4: 38 | J4: 16 | K4: =SUM(D4:J4) -> 227 | L4: =+B4&" "&C4 -> 1Q WK 03 | N4: 1Q WK 02 | O4: 290
A5: 2025 | B5: 1Q | C5: WK 04 | D5: 83 | E5: 13 | F5: 31 | G5: 6 | H5: 39 | I5: 39 | J5: 17 | K5: =SUM(D5:J5) -> 228 | L5: =+B5&" "&C5 -> 1Q WK 04 | N5: 1Q WK 03 | O5: 227
A6: 2025 | B6: 1Q | C6: WK 05 | D6: 77 | E6: 15 | F6: 29 | G6: 5 | H6: 37 | I6: 34 | J6: 17 | K6: =SUM(D6:J6) -> 214 | L6: =+B6&" "&C6 -> 1Q WK 05 | N6: 1Q WK 04 | O6: 228
A7: 2025 | B7: 1Q | C7: WK 06 | D7: 83 | E7: 22 | F7: 29 | G7: 8 | H7: 34 | I7: 32 | J7: 17 | K7: =SUM(D7:J7) -> 225 | L7: =+B7&" "&C7 -> 1Q WK 06 | N7: 1Q WK 05 | O7: 214
A8: 2025 | B8: 1Q | C8: WK 07 | D8: 78 | E8: 22 | F8: 25 | G8: 8 | H8: 25 | I8: 32 | J8: 17 | K8: =SUM(D8:J8) -> 207 | L8: =+B8&" "&C8 -> 1Q WK 07 | N8: 1Q WK 06 | O8: 225
A9: 2025 | B9: 1Q | C9: WK 08 | D9: 75 | E9: 22 | F9: 18 | G9: 9 | H9: 27 | I9: 36 | J9: 13 | K9: =SUM(D9:J9) -> 200 | L9: =+B9&" "&C9 -> 1Q WK 08 | N9: 1Q WK 07 | O9: 207
A10: 2025 | B10: 1Q | C10: WK 09 | D10: 63 | E10: 24 | F10: 16 | G10: 10 | H10: 30 | I10: 34 | J10: 12 | K10: =SUM(D10:J10) -> 189 | L10: =+B10&" "&C10 -> 1Q WK 09 | N10: 1Q WK 08 | O10: 200
A11: 2025 | B11: 1Q | C11: WK 10 | D11: 63 | E11: 23 | F11: 14 | G11: 9 | H11: 28 | I11: 31 | J11: 12 | K11: =SUM(D11:J11) -> 180 | L11: =+B11&" "&C11 -> 1Q WK 10 | N11: 1Q WK 09 | O11: 189
A12: 2025 | B12: 1Q | C12: WK 11 | D12: 60 | E12: 19 | F12: 11 | G12: 9 | H12: 23 | I12: 32 | J12: 13 | K12: =SUM(D12:J12) -> 167 | L12: =+B12&" "&C12 -> 1Q WK 11 | N12: 1Q WK 10 | O12: 180
A13: 2025 | B13: 1Q | C13: WK 12 | D13: 51 | E13: 20 | F13: 8 | G13: 8 | H13: 22 | I13: 32 | J13: 13 | K13: =SUM(D13:J13) -> 154 | L13: =+B13&" "&C13 -> 1Q WK 12 | N13: 1Q WK 11 | O13: 167
A14: 2025 | B14: 1Q | C14: WK 13 | D14: 51 | E14: 17 | F14: 8 | G14: 7 | H14: 19 | I14: 32 | J14: 14 | K14: =SUM(D14:J14) -> 148 | L14: =+B14&" "&C14 -> 1Q WK 13 | N14: 1Q WK 12 | O14: 154
... A22: 2025 | B22: 2Q | C22: WK 08 | D22: 38 | E22: 18 | F22: 18 | G22: 9 | H22: 25 | I22: 22 | J22: 16 | K22: =SUM(D22:J22) -> 146 | L22: =+B22&" "&C22 -> 2Q WK 08 | N22: 2Q WK 07 | O22: 147
A23: 2025 | B23: 2Q | C23: WK 09 | D23: 42 | E23: 16 | F23: 18 | G23: 10 | H23: 25 | I23: 19 | J23: 18 | K23: =SUM(D23:J23) -> 148 | L23: =+B23&" "&C23 -> 2Q WK 09 | N23: 2Q WK 08 | O23: 146 | Q23: Row Labels | R23: Sum of NA CIC
A24: 2025 | B24: 2Q | C24: WK 10 | D24: 50 | E24: 19 | F24: 21 | G24: 9 | H24: 24 | I24: 24 | J24: 14 | K24: =SUM(D24:J24) -> 161 | L24: =+B24&" "&C24 -> 2Q WK 10 | N24: 2Q WK 09 | O24: 148 | Q24: 1Q WK 01 | R24: 268
A25: 2025 | B25: 2Q | C25: WK 11 | D25: 52 | E25: 18 | F25: 21 | G25: 8 | H25: 26 | I25: 22 | J25: 12 | K25: =SUM(D25:J25) -> 159 | L25: =+B25&" "&C25 -> 2Q WK 11 | N25: 2Q WK 10 | O25: 161 | Q25: 1Q WK 02 | R25: 290
A26: 2025 | B26: 2Q | C26: WK 12 | D26: 40 | E26: 13 | F26: 20 | G26: 8 | H26: 21 | I26: 20 | J26: 11 | K26: =SUM(D26:J26) -> 133 | L26: =+B26&" "&C26 -> 2Q WK 12 | N26: 2Q WK 11 | O26: 159 | Q26: 1Q WK 03 | R26: 227
A27: 2025 | B27: 2Q | C27: WK 13 | D27: 47 | E27: 18 | F27: 23 | G27: 9 | H27: 20 | I27: 20 | J27: 11 | K27: =SUM(D27:J27) -> 148 | L27: =+B27&" "&C27 -> 2Q WK 13 | N27: 2Q WK 12 | O27: 133 | Q27: 1Q WK 04 | R27: 228
A28: 2025 | B28: 3Q | C28: WK 01 | D28: 57 | E28: 36 | F28: 24 | G28: 13 | H28: 18 | I28: 20 | J28: 13 | K28: =SUM(D28:J28) -> 181 | L28: =+B28&" "&C28 -> 3Q WK 01 | N28: 2Q WK 13 | O28: 148 | Q28: 1Q WK 05 | R28: 214
A29: 2025 | B29: 3Q | C29: WK 02 | D29: 53 | E29: 34 | F29: 23 | G29: 14 | H29: 19 | I29: 21 | J29: 13 | K29: =SUM(D29:J29) -> 177 | L29: =+B29&" "&C29 -> 3Q WK 02 | N29: 3Q WK 01 | O29: 181 | Q29: 1Q WK 06 | R29: 225
A30: 2025 | B30: 3Q | C30: WK 03 | D30: 55 | E30: 31 | F30: 17 | G30: 15 | H30: 19 | I30: 17 | J30: 11 | K30: =SUM(D30:J30) -> 165 | L30: =+B30&" "&C30 -> 3Q WK 03 | N30: 3Q WK 02 | O30: 177 | Q30: 1Q WK 07 | R30: 207
A31: 2025 | B31: 3Q | C31: WK 04 | D31: 56 | E31: 34 | F31: 15 | G31: 16 | H31: 19 | I31: 17 | J31: 11 | K31: =SUM(D31:J31) -> 168 | L31: =+B31&" "&C31 -> 3Q WK 04 | N31: 3Q WK 03 | O31: 165 | Q31: 1Q WK 08 | R31: 200
A32: 2025 | B32: 3Q | C32: WK 05 | D32: 49 | E32: 34 | F32: 14 | G32: 16 | H32: 15 | I32: 12 | J32: 6 | K32: =SUM(D32:J32) -> 146 | L32: =+B32&" "&C32 -> 3Q WK 05 | N32: 3Q WK 04 | O32: 168 | Q32: 1Q WK 09 | R32: 189
A33: 2025 | B33: 3Q | C33: WK 06 | D33: 47 | E33: 39 | F33: 15 | G33: 17 | H33: 14 | I33: 18 | J33: 6 | K33: 156 | L33: =+B33&" "&C33 -> 3Q WK 06 | N33: 3Q WK 05 | O33: 146 | Q33: 1Q WK 10 | R33: 180
A34: 2025 | B34: 3Q | C34: WK 07 | D34: 46 | E34: 41 | F34: 12 | G34: 19 | H34: 16 | I34: 18 | J34: 6 | K34: 158 | L34: =+B34&" "&C34 -> 3Q WK 07 | N34: 3Q WK 06 | O34: 156 | Q34: 1Q WK 11 | R34: 167
A35: 2025 | B35: 3Q | C35: WK 08 | D35: 45 | E35: 40 | F35: 11 | G35: 16 | H35: 11 | I35: 15 | J35: 5 | K35: =SUM(D35:J35) -> 143 | L35: =+B35&" "&C35 -> 3Q WK 08 | N35: 3Q WK 07 | O35: 158 | Q35: 1Q WK 12 | R35: 154
A36: 2025 | B36: 3Q | C36: WK 09 | D36: 40 | E36: 38 | F36: 11 | G36: 13 | H36: 8 | I36: 15 | J36: 3 | K36: 128 | L36: =+B36&" "&C36 -> 3Q WK 09 | N36: 3Q WK 08 | O36: 143 | Q36: 1Q WK 13 | R36: 148
A37: 2025 | B37: 3Q | C37: WK 10 | D37: 35 | E37: 37 | F37: 13 | G37: 15 | H37: 12 | I37: 18 | J37: 4 | K37: 134 | L37: =+B37&" "&C37 -> 3Q WK 10 | N37: 3Q WK 09 | O37: 128 | Q37: 2Q WK 01 | R37: 169
A38: 2025 | B38: 3Q | C38: WK 11 | D38: 28 | E38: 36 | F38: 13 | G38: 14 | H38: 10 | I38: 19 | J38: 3 | K38: 123 | L38: =+B38&" "&C38 -> 3Q WK 11 | N38: 3Q WK 10 | O38: 134 | Q38: 2Q WK 02 | R38: 142
A39: 2025 | B39: 3Q | C39: WK 12 | D39: 28 | E39: 38 | F39: 11 | G39: 15 | H39: 11 | I39: 16 | J39: 4 | K39: 123 | L39: =+B39&" "&C39 -> 3Q WK 12 | N39: 3Q WK 11 | O39: 123 | Q39: 2Q WK 03 | R39: 169
A40: 2025 | B40: 3Q | C40: WK 13 | D40: 27 | E40: 34 | F40: 11 | G40: 10 | H40: 11 | I40: 13 | J40: 6 | K40: 112 | L40: =+B40&" "&C40 -> 3Q WK 13 | N40: 3Q WK 12 | O40: 123 | Q40: 2Q WK 04 | R40: 155
A41: 2025 | B41: 4Q | C41: WK 01 | D41: 32 | E41: 34 | F41: 7 | G41: 12 | H41: 13 | I41: 17 | J41: 4 | K41: =SUM(D41:J41) -> 119 | L41: =+B41&" "&C41 -> 4Q WK 01 | N41: 3Q WK 13 | O41: 112 | Q41: 2Q WK 05 | R41: 164
A42: 2025 | B42: 4Q | C42: WK 02 | D42: 28 | E42: 28 | F42: 8 | G42: 12 | H42: 11 | I42: 13 | J42: 7 | K42: =SUM(D42:J42) -> 107 | L42: =+B42&" "&C42 -> 4Q WK 02 | N42: 4Q WK 01 | O42: 119 | Q42: 2Q WK 06 | R42: 136
A43: 2025 | B43: 4Q | C43: WK 03 | D43: 35 | E43: 26 | F43: 8 | G43: 13 | H43: 6 | I43: 15 | J43: 7 | K43: =SUM(D43:J43) -> 110 | L43: =+B43&" "&C43 -> 4Q WK 03 | N43: 4Q WK 02 | O43: 107 | Q43: 2Q WK 07 | R43: 147
A44: 2025 | B44: 4Q | C44: WK 04 | D44: 39 | E44: 26 | F44: 8 | G44: 12 | H44: 9 | I44: 37 | J44: 6 | K44: =SUM(D44:J44) -> 137 | L44: =+B44&" "&C44 -> 4Q WK 04 | N44: 4Q WK 03 | O44: 110 | Q44: 2Q WK 08 | R44: 146
A45: 2025 | B45: 4Q | C45: WK 05 | D45: 37 | E45: 24 | F45: 7 | G45: 10 | H45: 6 | I45: 36 | J45: 4 | K45: =SUM(D45:J45) -> 124 | L45: =+B45&" "&C45 -> 4Q WK 05 | N45: 4Q WK 04 | O45: 137 | Q45: 2Q WK 09 | R45: 148
A46: 2025 | B46: 4Q | C46: WK 06 | D46: 41 | E46: 25 | F46: 8 | G46: 10 | H46: 6 | I46: 34 | J46: 3 | K46: =SUM(D46:J46) -> 127 | L46: =+B46&" "&C46 -> 4Q WK 06 | N46: 4Q WK 05 | O46: 124 | Q46: 2Q WK 10 | R46: 161
A47: 2025 | B47: 4Q | C47: WK 07 | D47: 39 | E47: 15 | F47: 4 | G47: 6 | H47: 4 | I47: 23 | J47: 10 | K47: =SUM(D47:J47) -> 101 | L47: =+B47&" "&C47 -> 4Q WK 07 | N47: 4Q WK 06 | O47: 127 | Q47: 2Q WK 11 | R47: 159
...

Sheet Q3 2025
B1: Q4
A2: Center | B2: W1 | D2: W2 | F2: W3 | H2: W4 | J2: W5 | L2: W6 | N2: W7 | P2: W8 | R2: W9 | T2: W10 | V2: W11 | X2: W12 | Z2: W13
B3: Actual | D3: Actual | F3: Actual | H3: Actual | J3: Actual | L3: Actual | N3: Actual | P3: Actual | R3: Actual | T3: Actual | V3: Actual | X3: Actual | Z3: Fcst
B4: BBD | C4: Net | D4: BBD | E4: Net | F4: BBD | G4: Net | H4: BBD | I4: Net | J4: BBD | K4: Net | L4: BBD | M4: Net | N4: BBD | O4: Net | P4: BBD | Q4: Net | R4: BBD | S4: Net | T4: BBD | U4: Net | V4: BBD | W4: Net | X4: BBD | Y4: Net | Z4: BBD | AA4: Net
A5: Baton Rouge | B5: 32 | C5: 28 | D5: 28 | E5: 27 | F5: 35 | G5: 35 | H5: 39 | I5: 37 | J5: 37 | K5: 35 | L5: 41 | M5: 37 | N5: 41 | O5: 39 | P5: 39 | Q5: 34 | R5: 40 | S5: 36 | T5: 51 | U5: 48 | V5: 36 | W5: 31 | X5: 36 | Y5: 33 | Z5: 38 | AA5: 34
A6: Lansing | B6: 34 | C6: 26 | D6: 28 | E6: 23 | F6: 26 | G6: 23 | H6: 26 | I6: 23 | J6: 24 | K6: 22 | L6: 25 | M6: 20 | N6: 18 | O6: 15 | P6: 17 | Q6: 15 | R6: 19 | S6: 17 | T6: 20 | U6: 13 | V6: 17 | W6: 12 | X6: 16 | Y6: 12 | Z6: 18 | AA6: 15
A7: Monroe | B7: 7 | C7: 5 | D7: 8 | E7: 3 | F7: 8 | G7: 3 | H7: 8 | I7: 4 | J7: 7 | K7: 4 | L7: 8 | M7: 5 | N7: 7 | O7: 4 | P7: 8 | Q7: 4 | R7: 10 | S7: 5 | T7: 8 | U7: 6 | V7: 8 | W7: 6 | X7: 9 | Y7: 6 | Z7: 10 | AA7: 7
A8: Buffalo | B8: 12 | C8: 9 | D8: 12 | E8: 11 | F8: 13 | G8: 10 | H8: 12 | I8: 7 | J8: 10 | K8: 8 | L8: 10 | M8: 7 | N8: 6 | O8: 6 | P8: 6 | Q8: 6 | R8: 6 | S8: 6 | T8: 8 | U8: 7 | V8: 5 | W8: 4 | X8: 5 | Y8: 4 | Z8: 4 | AA8: 4
A9: Halifax | B9: 13 | C9: 11 | D9: 11 | E9: 10 | F9: 6 | G9: 6 | H9: 9 | I9: 3 | J9: 6 | K9: 2 | L9: 6 | M9: 3 | N9: 5 | O9: 4 | P9: 7 | Q9: 4 | R9: 9 | S9: 7 | T9: 10 | U9: 7 | V9: 8 | W9: 4 | X9: 14 | Y9: 7 | Z9: 18 | AA9: 11
A10: Quebec | B10: 17 | C10: 9 | D10: 13 | E10: 9 | F10: 15 | G10: 10 | H10: 37 | I10: 28 | J10: 36 | K10: 20 | L10: 34 | M10: 28 | N10: 32 | O10: 23 | P10: 26 | Q10: 19 | R10: 27 | S10: 19 | T10: 19 | U10: 15 | V10: 18 | W10: 12 | X10: 19 | Y10: 10 | Z10: 19 | AA10: 10
A11: Calgary | B11: 4 | C11: 2 | D11: 7 | E11: 6 | F11: 7 | G11: 3 | H11: 6 | I11: 2 | J11: 4 | K11: 2 | L11: 3 | M11: 2 | N11: 13 | O11: 10 | P11: 13 | Q11: 11 | R11: 13 | S11: 11 | T11: 18 | U11: 17 | V11: 21 | W11: 17 | X11: 19 | Y11: 16 | Z11: 20 | AA11: 17
A13: NA | B13: 119 | C13: 90 | D13: 107 | E13: 89 | F13: 110 | G13: 90 | H13: 137 | I13: 104 | J13: 124 | K13: 93 | L13: 127 | M13: 102 | N13: 122 | O13: 101 | P13: 116 | Q13: 93 | R13: 124 | S13: 101 | T13: 134 | U13: 113 | V13: 113 | W13: 86 | X13: 118 | Y13: 88 | Z13: 127 | AA13: 98
A15: Center | B15: W1 | C15: W2 | D15: W3 | E15: W4 | F15: W5 | G15: W6 | H15: W7 | I15: W8 | J15: W9 | K15: W10 | L15: W11 | M15: W12 | N15: W13
B16: Net | C16: Net | D16: Net | E16: Net | F16: Net | G16: Net | H16: Net | I16: Net | J16: Net | K16: Net | L16: Net | M16: Net | N16: Net
A17: Baton Rouge | B17: =+C5 -> 28 | C17: =+E5 -> 27 | D17: =+G5 -> 35 | E17: =+I5 -> 37 | F17: =+K5 -> 35 | G17: =+M5 -> 37 | H17: =+O5 -> 39 | I17: =+Q5 -> 34 | J17: =+S5 -> 36 | K17: =+U5 -> 48 | L17: =+W5 -> 31 | M17: =+Y5 -> 33 | N17: =+AA5 -> 34
A18: Lansing | B18: =+C6 -> 26 | C18: =+E6 -> 23 | D18: =+G6 -> 23 | E18: =+I6 -> 23 | F18: =+K6 -> 22 | G18: =+M6 -> 20 | H18: =+O6 -> 15 | I18: =+Q6 -> 15 | J18: =+S6 -> 17 | K18: =+U6 -> 13 | L18: =+W6 -> 12 | M18: =+Y6 -> 12 | N18: =+AA6 -> 15
A19: Monroe | B19: =+C7 -> 5 | C19: =+E7 -> 3 | D19: =+G7 -> 3 | E19: =+I7 -> 4 | F19: =+K7 -> 4 | G19: =+M7 -> 5 | H19: =+O7 -> 4 | I19: =+Q7 -> 4 | J19: =+S7 -> 5 | K19: =+U7 -> 6 | L19: =+W7 -> 6 | M19: =+Y7 -> 6 | N19: =+AA7 -> 7
A20: Buffalo | B20: =+C8 -> 9 | C20: =+E8 -> 11 | D20: =+G8 -> 10 | E20: =+I8 -> 7 | F20: =+K8 -> 8 | G20: =+M8 -> 7 | H20: =+O8 -> 6 | I20: =+Q8 -> 6 | J20: =+S8 -> 6 | K20: =+U8 -> 7 | L20: =+W8 -> 4 | M20: =+Y8 -> 4 | N20: =+AA8 -> 4
A21: Halifax | B21: =+C9 -> 11 | C21: =+E9 -> 10 | D21: =+G9 -> 6 | E21: =+I9 -> 3 | F21: =+K9 -> 2 | G21: =+M9 -> 3 | H21: =+O9 -> 4 | I21: =+Q9 -> 4 | J21: =+S9 -> 7 | K21: =+U9 -> 7 | L21: =+W9 -> 4 | M21: =+Y9 -> 7 | N21: =+AA9 -> 11
A22: Quebec | B22: =+C10 -> 9 | C22: =+E10 -> 9 | D22: =+G10 -> 10 | E22: =+I10 -> 28 | F22: =+K10 -> 20 | G22: =+M10 -> 28 | H22: =+O10 -> 23 | I22: =+Q10 -> 19 | J22: =+S10 -> 19 | K22: =+U10 -> 15 | L22: =+W10 -> 12 | M22: =+Y10 -> 10 | N22: =+AA10 -> 10
A23: Calgary | B23: =+C11 -> 2 | C23: =+E11 -> 6 | D23: =+G11 -> 3 | E23: =+I11 -> 2 | F23: =+K11 -> 2 | G23: =+M11 -> 2 | H23: =+O11 -> 10 | I23: =+Q11 -> 11 | J23: =+S11 -> 11 | K23: =+U11 -> 17 | L23: =+W11 -> 17 | M23: =+Y11 -> 16 | N23: =+AA11 -> 17
A25: NA | B25: =SUM(B17:B24) -> 90 | C25: =SUM(C17:C24) -> 89 | D25: =SUM(D17:D24) -> 90 | E25: =SUM(E17:E24) -> 104 | F25: =SUM(F17:F24) -> 93 | G25: =SUM(G17:G24) -> 102 | H25: =SUM(H17:H24) -> 101 | I25: =SUM(I17:I24) -> 93 | ... N25: =SUM(N17:N24) -> 98
A30: Total Bench | B30: Wk 01 | C30: Wk 02 | D30: Wk 03 | E30: Wk 04 | F30: Wk 05 | G30: Wk 06 | H30: Wk 07 | I30: Wk 08 | J30: Wk 09 | K30: Wk 10 | L30: Wk 11 | M30: Wk 12 | N30: Wk 13
A31: Q3 26 Forecast | B31: =+'Bench Forecast'!B9 -> 146 | C31: =+'Bench Forecast'!C9 -> 115 | D31: =+'Bench Forecast'!D9 -> 104 | E31: =+'Bench Forecast'!E9 -> 124 | F31: =+'Bench Forecast'!F9 -> 114 | G31: =+'Bench Forecast'!G9 -> 134 | H31: =+'Bench Forecast'!H9 -> 155 | I31: =+'Bench Forecast'!I9 -> 141 | ... N31: =+'Bench Forecast'!N9 -> 187
A32: Q3 25 bench | B32: =+B25 -> 90 | C32: =+C25 -> 89 | D32: =+D25 -> 90 | E32: =+E25 -> 104 | F32: =+F25 -> 93 | G32: =+G25 -> 102 | H32: =+H25 -> 101 | I32: =+I25 -> 93 | ... N32: =+N25 -> 98
A33: Q3 Original Forecast | B33: 159 | C33: 161 | D33: 154 | E33: 156 | F33: 152 | G33: 165 | H33: 175 | I33: 176 | J33: 171 | K33: 196 | L33: 192 | M33: 191 | N33: 187
B36: Column Labels
A37: Week | B37: Q3 26 Forecast | C37: Q3 25 bench | D37: Q3 Original Forecast | E37: Grand Total
A38: Wk 01 | B38: 146 | C38: 90 | D38: 159 | E38: 395
A39: Wk 02 | B39: 115 | C39: 89 | D39: 161 | E39: 365
A40: Wk 03 | B40: 151 | C40: 90 | D40: 154 | E40: 395
A41: Wk 04 | B41: 132 | C41: 104 | D41: 156 | E41: 392
A42: Wk 05 | B42: 120 | C42: 93 | D42: 152 | E42: 365
A43: Wk 06 | B43: 142 | C43: 102 | D43: 165 | E43: 409
A44: Wk 07 | B44: 155 | C44: 101 | D44: 175 | E44: 431
A45: Wk 08 | B45: 160 | C45: 93 | D45: 176 | E45: 429
A46: Wk 09 | B46: 161 | C46: 101 | D46: 171 | E46: 433
A47: Wk 10 | B47: 203 | C47: 113 | D47: 196 | E47: 512
A48: Wk 11 | B48: 215 | C48: 86 | D48: 192 | E48: 493
A49: Wk 12 | B49: 214 | C49: 88 | D49: 191 | E49: 493
...
